Workbook

Sheet TRACKER
A1: HABIT TRACKER
A2: =TEXT(DATE(CONFIG!C4,CONFIG!C5,1),"mmmm yyyy")&" · seguimiento mensual" -> September 2026 · seguimiento mensual
B3: HÁBITOS | E3: COMPLETADOS | H3: PROGRESO | K3: RACHA | N3: FEELING 😊
B4: =10 -> 10 | E4: =SUM(C10:AG19) -> 2 | H4: =IFERROR(SUM(C10:AG19)/(DAY(EOMONTH(DATE(CONFIG!C4,CONFIG!C5,1),0))*10),0) -> 0.0066666667 | K4: =IFERROR(INDEX(C24:AG24,SUMPRODUCT(MAX((C24:AG24<>"")*COLUMN(C24:AG24)))-COLUMN(C24)+1),0) -> 1 | N4: =IFERROR(AVERAGEIF(C22:AG22,">0",C22:AG22),0) -> 6.3333333 | Q4: =REPT("■",ROUND(H4*30,0))&REPT("·",30-ROUND(H4*30,0)) -> ······························
A8: HÁBITO | B8: TOTAL | C8: =IF(DAY(EOMONTH(DATE(CONFIG!C4,CONFIG!C5,1),0))>=1,"W1","") -> W1 | D8: =IF(DAY(EOMONTH(DATE(CONFIG!C4,CONFIG!C5,1),0))>=2,"W1","") -> W1 | E8: =IF(DAY(EOMONTH(DATE(CONFIG!C4,CONFIG!C5,1),0))>=3,"W1","") -> W1 | F8: =IF(DAY(EOMONTH(DATE(CONFIG!C4,CONFIG!C5,1),0))>=4,"W1","") -> W1 | G8: =IF(DAY(EOMONTH(DATE(CONFIG!C4,CONFIG!C5,1),0))>=5,"W1","") -> W1 | H8: =IF(DAY(EOMONTH(DATE(CONFIG!C4,CONFIG!C5,1),0))>=6,"W1","") -> W1 | I8: =IF(DAY(EOMONTH(DATE(CONFIG!C4,CONFIG!C5,1),0))>=7,"W1","") -> W1 | J8: =IF(DAY(EOMONTH(DATE(CONFIG!C4,CONFIG!C5,1),0))>=8,"W2","") -> W2 | K8: =IF(DAY(EOMONTH(DATE(CONFIG!C4,CONFIG!C5,1),0))>=9,"W2","") -> W2 | L8: =IF(DAY(EOMONTH(DATE(CONFIG!C4,CONFIG!C5,1),0))>=10,"W2","") -> W2 | M8: =IF(DAY(EOMONTH(DATE(CONFIG!C4,CONFIG!C5,1),0))>=11,"W2","") -> W2 | N8: =IF(DAY(EOMONTH(DATE(CONFIG!C4,CONFIG!C5,1),0))>=12,"W2","") -> W2 | O8: =IF(DAY(EOMONTH(DATE(CONFIG!C4,CONFIG!C5,1),0))>=13,"W2","") -> W2 | P8: =IF(DAY(EOMONTH(DATE(CONFIG!C4,CONFIG!C5,1),0))>=14,"W2","") -> W2 | Q8: =IF(DAY(EOMONTH(DATE(CONFIG!C4,CONFIG!C5,1),0))>=15,"W3","") -> W3 | R8: =IF(DAY(EOMONTH(DATE(CONFIG!C4,CONFIG!C5,1),0))>=16,"W3","") -> W3 | S8: =IF(DAY(EOMONTH(DATE(CONFIG!C4,CONFIG!C5,1),0))>=17,"W3","") -> W3 | T8: =IF(DAY(EOMONTH(DATE(CONFIG!C4,CONFIG!C5,1),0))>=18,"W3","") -> W3 | U8: =IF(DAY(EOMONTH(DATE(CONFIG!C4,CONFIG!C5,1),0))>=19,"W3","") -> W3 | V8: =IF(DAY(EOMONTH(DATE(CONFIG!C4,CONFIG!C5,1),0))>=20,"W3","") -> W3 | W8: =IF(DAY(EOMONTH(DATE(CONFIG!C4,CONFIG!C5,1),0))>=21,"W3","") -> W3 | X8: =IF(DAY(EOMONTH(DATE(CONFIG!C4,CONFIG!C5,1),0))>=22,"W4","") -> W4 | Y8: =IF(DAY(EOMONTH(DATE(CONFIG!C4,CONFIG!C5,1),0))>=23,"W4","") -> W4 | Z8: =IF(DAY(EOMONTH(DATE(CONFIG!C4,CONFIG!C5,1),0))>=24,"W4","") -> W4 | AA8: =IF(DAY(EOMONTH(DATE(CONFIG!C4,CONFIG!C5,1),0))>=25,"W4","") -> W4 | AB8: =IF(DAY(EOMONTH(DATE(CONFIG!C4,CONFIG!C5,1),0))>=26,"W4","") -> W4 | AC8: =IF(DAY(EOMONTH(DATE(CONFIG!C4,CONFIG!C5,1),0))>=27,"W4","") -> W4 | AD8: =IF(DAY(EOMONTH(DATE(CONFIG!C4,CONFIG!C5,1),0))>=28,"W4","") -> W4 | AE8: =IF(DAY(EOMONTH(DATE(CONFIG!C4,CONFIG!C5,1),0))>=29,"W5","") -> W5 | AF8: =IF(DAY(EOMONTH(DATE(CONFIG!C4,CONFIG!C5,1),0))>=30,"W5","") -> W5 | AG8: =IF(DAY(EOMONTH(DATE(CONFIG!C4,CONFIG!C5,1),0))>=31,"W5","")
C9: =IF(DAY(EOMONTH(DATE(CONFIG!C4,CONFIG!C5,1),0))>=1,"1","") -> 1 | D9: =IF(DAY(EOMONTH(DATE(CONFIG!C4,CONFIG!C5,1),0))>=2,"2","") -> 2 | E9: =IF(DAY(EOMONTH(DATE(CONFIG!C4,CONFIG!C5,1),0))>=3,"3","") -> 3 | F9: =IF(DAY(EOMONTH(DATE(CONFIG!C4,CONFIG!C5,1),0))>=4,"4","") -> 4 | G9: =IF(DAY(EOMONTH(DATE(CONFIG!C4,CONFIG!C5,1),0))>=5,"5","") -> 5 | H9: =IF(DAY(EOMONTH(DATE(CONFIG!C4,CONFIG!C5,1),0))>=6,"6","") -> 6 | I9: =IF(DAY(EOMONTH(DATE(CONFIG!C4,CONFIG!C5,1),0))>=7,"7","") -> 7 | J9: =IF(DAY(EOMONTH(DATE(CONFIG!C4,CONFIG!C5,1),0))>=8,"8","") -> 8 | K9: =IF(DAY(EOMONTH(DATE(CONFIG!C4,CONFIG!C5,1),0))>=9,"9","") -> 9 | L9: =IF(DAY(EOMONTH(DATE(CONFIG!C4,CONFIG!C5,1),0))>=10,"10","") -> 10 | M9: =IF(DAY(EOMONTH(DATE(CONFIG!C4,CONFIG!C5,1),0))>=11,"11","") -> 11 | N9: =IF(DAY(EOMONTH(DATE(CONFIG!C4,CONFIG!C5,1),0))>=12,"12","") -> 12 | O9: =IF(DAY(EOMONTH(DATE(CONFIG!C4,CONFIG!C5,1),0))>=13,"13","") -> 13 | P9: =IF(DAY(EOMONTH(DATE(CONFIG!C4,CONFIG!C5,1),0))>=14,"14","") -> 14 | Q9: =IF(DAY(EOMONTH(DATE(CONFIG!C4,CONFIG!C5,1),0))>=15,"15","") -> 15 | R9: =IF(DAY(EOMONTH(DATE(CONFIG!C4,CONFIG!C5,1),0))>=16,"16","") -> 16 | S9: =IF(DAY(EOMONTH(DATE(CONFIG!C4,CONFIG!C5,1),0))>=17,"17","") -> 17 | T9: =IF(DAY(EOMONTH(DATE(CONFIG!C4,CONFIG!C5,1),0))>=18,"18","") -> 18 | U9: =IF(DAY(EOMONTH(DATE(CONFIG!C4,CONFIG!C5,1),0))>=19,"19","") -> 19 | V9: =IF(DAY(EOMONTH(DATE(CONFIG!C4,CONFIG!C5,1),0))>=20,"20","") -> 20 | W9: =IF(DAY(EOMONTH(DATE(CONFIG!C4,CONFIG!C5,1),0))>=21,"21","") -> 21 | X9: =IF(DAY(EOMONTH(DATE(CONFIG!C4,CONFIG!C5,1),0))>=22,"22","") -> 22 | Y9: =IF(DAY(EOMONTH(DATE(CONFIG!C4,CONFIG!C5,1),0))>=23,"23","") -> 23 | Z9: =IF(DAY(EOMONTH(DATE(CONFIG!C4,CONFIG!C5,1),0))>=24,"24","") -> 24 | AA9: =IF(DAY(EOMONTH(DATE(CONFIG!C4,CONFIG!C5,1),0))>=25,"25","") -> 25 | AB9: =IF(DAY(EOMONTH(DATE(CONFIG!C4,CONFIG!C5,1),0))>=26,"26","") -> 26 | AC9: =IF(DAY(EOMONTH(DATE(CONFIG!C4,CONFIG!C5,1),0))>=27,"27","") -> 27 | AD9: =IF(DAY(EOMONTH(DATE(CONFIG!C4,CONFIG!C5,1),0))>=28,"28","") -> 28 | AE9: =IF(DAY(EOMONTH(DATE(CONFIG!C4,CONFIG!C5,1),0))>=29,"29","") -> 29 | AF9: =IF(DAY(EOMONTH(DATE(CONFIG!C4,CONFIG!C5,1),0))>=30,"30","") -> 30 | AG9: =IF(DAY(EOMONTH(DATE(CONFIG!C4,CONFIG!C5,1),0))>=31,"31","")
A10: =CONFIG!B9 -> Estudiar | B10: =SUM(C10:AG10) -> 2 | C10: 1 | E10: 1
A11: =CONFIG!B10 -> Entrenar | B11: =SUM(C11:AG11) -> 0
A12: =CONFIG!B11 -> Modulo Inglés | B12: =SUM(C12:AG12) -> 0
A13: =CONFIG!B12 -> -Flashcards | B13: =SUM(C13:AG13) -> 0
A14: =CONFIG!B13 -> -Input / idioma | B14: =SUM(C14:AG14) -> 0
A15: =CONFIG!B14 -> -Lectura english | B15: =SUM(C15:AG15) -> 0
A16: =CONFIG!B15 -> -Grammar | B16: =SUM(C16:AG16) -> 0
A17: =CONFIG!B16 -> -Input Gamer | B17: =SUM(C17:AG17) -> 0 | D17: 0
A18: =CONFIG!B17 -> Leer 1h | B18: =SUM(C18:AG18) -> 0
A19: =CONFIG!B18 -> Mindfulness | B19: =SUM(C19:AG19) -> 0
A21: DAILY CHECK-IN
A22: FEELING 😊 | C22: 7 | D22: 4 | E22: 8
A23: TODO OK? | C23: SI | D23: NO | E23: SI
A24: RACHA | C24: =IF(C23="SI",IF(C23="","",IF(COLUMN()=3,1,B24+1)),IF(C23="","",0)) -> 1 | D24: =IF(D23="SI",IF(D23="","",IF(COLUMN()=3,1,C24+1)),IF(D23="","",0)) -> 0 | E24: =IF(E23="SI",IF(E23="","",IF(COLUMN()=3,1,D24+1)),IF(E23="","",0)) -> 1 | F24: =IF(F23="SI",IF(F23="","",IF(COLUMN()=3,1,E24+1)),IF(F23="","",0)) | G24: =IF(G23="SI",IF(G23="","",IF(COLUMN()=3,1,F24+1)),IF(G23="","",0)) | H24: =IF(H23="SI",IF(H23="","",IF(COLUMN()=3,1,G24+1)),IF(H23="","",0)) | I24: =IF(I23="SI",IF(I23="","",IF(COLUMN()=3,1,H24+1)),IF(I23="","",0)) | J24: =IF(J23="SI",IF(J23="","",IF(COLUMN()=3,1,I24+1)),IF(J23="","",0)) | ... AG24: =IF(AG23="SI",IF(AG23="","",IF(COLUMN()=3,1,AF24+1)),IF(AG23="","",0))
A25: SUEÑO (hs)
A26: CALORÍAS
A27: NOTAS / HECHOS RELEVANTES
A28: Escribí acá victorias, aprendizajes, errores, decisiones o cualquier hecho que quieras recordar.
A34: EVOLUCIÓN MENSUAL DE HÁBITOS
A36: % DÍA | B36: % cumplido | C36: =IFERROR(SUM(C10:C19)/10,0) -> 0.1 | D36: =IFERROR(SUM(D10:D19)/10,0) -> 0 | E36: =IFERROR(SUM(E10:E19)/10,0) -> 0.1 | F36: =IFERROR(SUM(F10:F19)/10,0) -> 0 | G36: =IFERROR(SUM(G10:G19)/10,0) -> 0 | H36: =IFERROR(SUM(H10:H19)/10,0) -> 0 | I36: =IFERROR(SUM(I10:I19)/10,0) -> 0 | J36: =IFERROR(SUM(J10:J19)/10,0) -> 0 | ... AG36: =IFERROR(SUM(AG10:AG19)/10,0) -> 0
A37: OBJETIVO | B37: Objetivo | C37: =CONFIG!$C$6/100 -> 0.8 | D37: =CONFIG!$C$6/100 -> 0.8 | E37: =CONFIG!$C$6/100 -> 0.8 | F37: =CONFIG!$C$6/100 -> 0.8 | G37: =CONFIG!$C$6/100 -> 0.8 | H37: =CONFIG!$C$6/100 -> 0.8 | I37: =CONFIG!$C$6/100 -> 0.8 | J37: =CONFIG!$C$6/100 -> 0.8 | ... AG37: =CONFIG!$C$6/100 -> 0.8

Sheet SEMANA
B2: SEGUIMIENTO SEMANAL
B3: =TEXT(DATE(CONFIG!$C$4,CONFIG!$C$5,1),"mmmm yyyy")&" · elegí la semana para ver el detalle día a día" -> September 2026 · elegí la semana para ver el detalle día a día | T3: SEMANA | U3: 1
B5: =UPPER("LUNES "&(($U$3-1)*7+1)) -> LUNES 1 | E5: =UPPER("MARTES "&(($U$3-1)*7+2)) -> MARTES 2 | H5: =UPPER("MIÉRCOLES "&(($U$3-1)*7+3)) -> MIÉRCOLES 3 | K5: =UPPER("JUEVES "&(($U$3-1)*7+4)) -> JUEVES 4 | N5: =UPPER("VIERNES "&(($U$3-1)*7+5)) -> VIERNES 5 | Q5: =UPPER("SÁBADO "&(($U$3-1)*7+6)) -> SÁBADO 6 | T5: =UPPER("DOMINGO "&(($U$3-1)*7+7)) -> DOMINGO 7
B6: =TEXT(A60,"0%") -> 10% | E6: =TEXT(A61,"0%") -> 0% | H6: =TEXT(A62,"0%") -> 10% | K6: =TEXT(A63,"0%") -> 0% | N6: =TEXT(A64,"0%") -> 0% | Q6: =TEXT(A65,"0%") -> 0% | T6: =TEXT(A66,"0%") -> 0%
B7: =ROUND(A60*10,0)&"/10 hábitos" -> 1/10 hábitos | E7: =ROUND(A61*10,0)&"/10 hábitos" -> 0/10 hábitos | H7: =ROUND(A62*10,0)&"/10 hábitos" -> 1/10 hábitos | K7: =ROUND(A63*10,0)&"/10 hábitos" -> 0/10 hábitos | N7: =ROUND(A64*10,0)&"/10 hábitos" -> 0/10 hábitos | Q7: =ROUND(A65*10,0)&"/10 hábitos" -> 0/10 hábitos | T7: =ROUND(A66*10,0)&"/10 hábitos" -> 0/10 hábitos
B9: TAREAS DEL DÍA | E9: TAREAS DEL DÍA | H9: TAREAS DEL DÍA | K9: TAREAS DEL DÍA | N9: TAREAS DEL DÍA | Q9: TAREAS DEL DÍA | T9: TAREAS DEL DÍA
B10: =CONFIG!$B$9 -> Estudiar | C10: =IFERROR(OFFSET(TRACKER!$B$10,0,(($U$3-1)*7+1)),0) -> 1 | E10: =CONFIG!$B$9 -> Estudiar | F10: =IFERROR(OFFSET(TRACKER!$B$10,0,(($U$3-1)*7+2)),0) -> 0 | H10: =CONFIG!$B$9 -> Estudiar | I10: =IFERROR(OFFSET(TRACKER!$B$10,0,(($U$3-1)*7+3)),0) -> 1 | K10: =CONFIG!$B$9 -> Estudiar | L10: =IFERROR(OFFSET(TRACKER!$B$10,0,(($U$3-1)*7+4)),0) -> 0 | N10: =CONFIG!$B$9 -> Estudiar | O10: =IFERROR(OFFSET(TRACKER!$B$10,0,(($U$3-1)*7+5)),0) -> 0 | Q10: =CONFIG!$B$9 -> Estudiar | R10: =IFERROR(OFFSET(TRACKER!$B$10,0,(($U$3-1)*7+6)),0) -> 0 | T10: =CONFIG!$B$9 -> Estudiar | U10: =IFERROR(OFFSET(TRACKER!$B$10,0,(($U$3-1)*7+7)),0) -> 0
B11: =CONFIG!$B$10 -> Entrenar | C11: =IFERROR(OFFSET(TRACKER!$B$11,0,(($U$3-1)*7+1)),0) -> 0 | E11: =CONFIG!$B$10 -> Entrenar | F11: =IFERROR(OFFSET(TRACKER!$B$11,0,(($U$3-1)*7+2)),0) -> 0 | H11: =CONFIG!$B$10 -> Entrenar | I11: =IFERROR(OFFSET(TRACKER!$B$11,0,(($U$3-1)*7+3)),0) -> 0 | K11: =CONFIG!$B$10 -> Entrenar | L11: =IFERROR(OFFSET(TRACKER!$B$11,0,(($U$3-1)*7+4)),0) -> 0 | N11: =CONFIG!$B$10 -> Entrenar | O11: =IFERROR(OFFSET(TRACKER!$B$11,0,(($U$3-1)*7+5)),0) -> 0 | Q11: =CONFIG!$B$10 -> Entrenar | R11: =IFERROR(OFFSET(TRACKER!$B$11,0,(($U$3-1)*7+6)),0) -> 0 | T11: =CONFIG!$B$10 -> Entrenar | U11: =IFERROR(OFFSET(TRACKER!$B$11,0,(($U$3-1)*7+7)),0) -> 0
B12: =CONFIG!$B$11 -> Modulo Inglés | C12: =IFERROR(OFFSET(TRACKER!$B$12,0,(($U$3-1)*7+1)),0) -> 0 | E12: =CONFIG!$B$11 -> Modulo Inglés | F12: =IFERROR(OFFSET(TRACKER!$B$12,0,(($U$3-1)*7+2)),0) -> 0 | H12: =CONFIG!$B$11 -> Modulo Inglés | I12: =IFERROR(OFFSET(TRACKER!$B$12,0,(($U$3-1)*7+3)),0) -> 0 | K12: =CONFIG!$B$11 -> Modulo Inglés | L12: =IFERROR(OFFSET(TRACKER!$B$12,0,(($U$3-1)*7+4)),0) -> 0 | N12: =CONFIG!$B$11 -> Modulo Inglés | O12: =IFERROR(OFFSET(TRACKER!$B$12,0,(($U$3-1)*7+5)),0) -> 0 | Q12: =CONFIG!$B$11 -> Modulo Inglés | R12: =IFERROR(OFFSET(TRACKER!$B$12,0,(($U$3-1)*7+6)),0) -> 0 | T12: =CONFIG!$B$11 -> Modulo Inglés | U12: =IFERROR(OFFSET(TRACKER!$B$12,0,(($U$3-1)*7+7)),0) -> 0
B13: =CONFIG!$B$12 -> -Flashcards | C13: =IFERROR(OFFSET(TRACKER!$B$13,0,(($U$3-1)*7+1)),0) -> 0 | E13: =CONFIG!$B$12 -> -Flashcards | F13: =IFERROR(OFFSET(TRACKER!$B$13,0,(($U$3-1)*7+2)),0) -> 0 | H13: =CONFIG!$B$12 -> -Flashcards | I13: =IFERROR(OFFSET(TRACKER!$B$13,0,(($U$3-1)*7+3)),0) -> 0 | K13: =CONFIG!$B$12 -> -Flashcards | L13: =IFERROR(OFFSET(TRACKER!$B$13,0,(($U$3-1)*7+4)),0) -> 0 | N13: =CONFIG!$B$12 -> -Flashcards | O13: =IFERROR(OFFSET(TRACKER!$B$13,0,(($U$3-1)*7+5)),0) -> 0 | Q13: =CONFIG!$B$12 -> -Flashcards | R13: =IFERROR(OFFSET(TRACKER!$B$13,0,(($U$3-1)*7+6)),0) -> 0 | T13: =CONFIG!$B$12 -> -Flashcards | U13: =IFERROR(OFFSET(TRACKER!$B$13,0,(($U$3-1)*7+7)),0) -> 0
B14: =CONFIG!$B$13 -> -Input / idioma | C14: =IFERROR(OFFSET(TRACKER!$B$14,0,(($U$3-1)*7+1)),0) -> 0 | E14: =CONFIG!$B$13 -> -Input / idioma | F14: =IFERROR(OFFSET(TRACKER!$B$14,0,(($U$3-1)*7+2)),0) -> 0 | H14: =CONFIG!$B$13 -> -Input / idioma | I14: =IFERROR(OFFSET(TRACKER!$B$14,0,(($U$3-1)*7+3)),0) -> 0 | K14: =CONFIG!$B$13 -> -Input / idioma | L14: =IFERROR(OFFSET(TRACKER!$B$14,0,(($U$3-1)*7+4)),0) -> 0 | N14: =CONFIG!$B$13 -> -Input / idioma | O14: =IFERROR(OFFSET(TRACKER!$B$14,0,(($U$3-1)*7+5)),0) -> 0 | Q14: =CONFIG!$B$13 -> -Input / idioma | R14: =IFERROR(OFFSET(TRACKER!$B$14,0,(($U$3-1)*7+6)),0) -> 0 | T14: =CONFIG!$B$13 -> -Input / idioma | U14: =IFERROR(OFFSET(TRACKER!$B$14,0,(($U$3-1)*7+7)),0) -> 0
B15: =CONFIG!$B$14 -> -Lectura english | C15: =IFERROR(OFFSET(TRACKER!$B$15,0,(($U$3-1)*7+1)),0) -> 0 | E15: =CONFIG!$B$14 -> -Lectura english | F15: =IFERROR(OFFSET(TRACKER!$B$15,0,(($U$3-1)*7+2)),0) -> 0 | H15: =CONFIG!$B$14 -> -Lectura english | I15: =IFERROR(OFFSET(TRACKER!$B$15,0,(($U$3-1)*7+3)),0) -> 0 | K15: =CONFIG!$B$14 -> -Lectura english | L15: =IFERROR(OFFSET(TRACKER!$B$15,0,(($U$3-1)*7+4)),0) -> 0 | N15: =CONFIG!$B$14 -> -Lectura english | O15: =IFERROR(OFFSET(TRACKER!$B$15,0,(($U$3-1)*7+5)),0) -> 0 | Q15: =CONFIG!$B$14 -> -Lectura english | R15: =IFERROR(OFFSET(TRACKER!$B$15,0,(($U$3-1)*7+6)),0) -> 0 | T15: =CONFIG!$B$14 -> -Lectura english | U15: =IFERROR(OFFSET(TRACKER!$B$15,0,(($U$3-1)*7+7)),0) -> 0
B16: =CONFIG!$B$15 -> -Grammar | C16: =IFERROR(OFFSET(TRACKER!$B$16,0,(($U$3-1)*7+1)),0) -> 0 | E16: =CONFIG!$B$15 -> -Grammar | F16: =IFERROR(OFFSET(TRACKER!$B$16,0,(($U$3-1)*7+2)),0) -> 0 | H16: =CONFIG!$B$15 -> -Grammar | I16: =IFERROR(OFFSET(TRACKER!$B$16,0,(($U$3-1)*7+3)),0) -> 0 | K16: =CONFIG!$B$15 -> -Grammar | L16: =IFERROR(OFFSET(TRACKER!$B$16,0,(($U$3-1)*7+4)),0) -> 0 | N16: =CONFIG!$B$15 -> -Grammar | O16: =IFERROR(OFFSET(TRACKER!$B$16,0,(($U$3-1)*7+5)),0) -> 0 | Q16: =CONFIG!$B$15 -> -Grammar | R16: =IFERROR(OFFSET(TRACKER!$B$16,0,(($U$3-1)*7+6)),0) -> 0 | T16: =CONFIG!$B$15 -> -Grammar | U16: =IFERROR(OFFSET(TRACKER!$B$16,0,(($U$3-1)*7+7)),0) -> 0
B17: =CONFIG!$B$16 -> -Input Gamer | C17: =IFERROR(OFFSET(TRACKER!$B$17,0,(($U$3-1)*7+1)),0) -> 0 | E17: =CONFIG!$B$16 -> -Input Gamer | F17: =IFERROR(OFFSET(TRACKER!$B$17,0,(($U$3-1)*7+2)),0) -> 0 | H17: =CONFIG!$B$16 -> -Input Gamer | I17: =IFERROR(OFFSET(TRACKER!$B$17,0,(($U$3-1)*7+3)),0) -> 0 | K17: =CONFIG!$B$16 -> -Input Gamer | L17: =IFERROR(OFFSET(TRACKER!$B$17,0,(($U$3-1)*7+4)),0) -> 0 | N17: =CONFIG!$B$16 -> -Input Gamer | O17: =IFERROR(OFFSET(TRACKER!$B$17,0,(($U$3-1)*7+5)),0) -> 0 | Q17: =CONFIG!$B$16 -> -Input Gamer | R17: =IFERROR(OFFSET(TRACKER!$B$17,0,(($U$3-1)*7+6)),0) -> 0 | T17: =CONFIG!$B$16 -> -Input Gamer | U17: =IFERROR(OFFSET(TRACKER!$B$17,0,(($U$3-1)*7+7)),0) -> 0
B18: =CONFIG!$B$17 -> Leer 1h | C18: =IFERROR(OFFSET(TRACKER!$B$18,0,(($U$3-1)*7+1)),0) -> 0 | E18: =CONFIG!$B$17 -> Leer 1h | F18: =IFERROR(OFFSET(TRACKER!$B$18,0,(($U$3-1)*7+2)),0) -> 0 | H18: =CONFIG!$B$17 -> Leer 1h | I18: =IFERROR(OFFSET(TRACKER!$B$18,0,(($U$3-1)*7+3)),0) -> 0 | K18: =CONFIG!$B$17 -> Leer 1h | L18: =IFERROR(OFFSET(TRACKER!$B$18,0,(($U$3-1)*7+4)),0) -> 0 | N18: =CONFIG!$B$17 -> Leer 1h | O18: =IFERROR(OFFSET(TRACKER!$B$18,0,(($U$3-1)*7+5)),0) -> 0 | Q18: =CONFIG!$B$17 -> Leer 1h | R18: =IFERROR(OFFSET(TRACKER!$B$18,0,(($U$3-1)*7+6)),0) -> 0 | T18: =CONFIG!$B$17 -> Leer 1h | U18: =IFERROR(OFFSET(TRACKER!$B$18,0,(($U$3-1)*7+7)),0) -> 0
B19: =CONFIG!$B$18 -> Mindfulness | C19: =IFERROR(OFFSET(TRACKER!$B$19,0,(($U$3-1)*7+1)),0) -> 0 | E19: =CONFIG!$B$18 -> Mindfulness | F19: =IFERROR(OFFSET(TRACKER!$B$19,0,(($U$3-1)*7+2)),0) -> 0 | H19: =CONFIG!$B$18 -> Mindfulness | I19: =IFERROR(OFFSET(TRACKER!$B$19,0,(($U$3-1)*7+3)),0) -> 0 | K19: =CONFIG!$B$18 -> Mindfulness | L19: =IFERROR(OFFSET(TRACKER!$B$19,0,(($U$3-1)*7+4)),0) -> 0 | N19: =CONFIG!$B$18 -> Mindfulness | O19: =IFERROR(OFFSET(TRACKER!$B$19,0,(($U$3-1)*7+5)),0) -> 0 | Q19: =CONFIG!$B$18 -> Mindfulness | R19: =IFERROR(OFFSET(TRACKER!$B$19,0,(($U$3-1)*7+6)),0) -> 0 | T19: =CONFIG!$B$18 -> Mindfulness | U19: =IFERROR(OFFSET(TRACKER!$B$19,0,(($U$3-1)*7+7)),0) -> 0
B20: =IF(A60>=CONFIG!$C$6/100,"✓ Día óptimo","En proceso") -> En proceso | E20: =IF(A61>=CONFIG!$C$6/100,"✓ Día óptimo","En proceso") -> En proceso | H20: =IF(A62>=CONFIG!$C$6/100,"✓ Día óptimo","En proceso") -> En proceso | K20: =IF(A63>=CONFIG!$C$6/100,"✓ Día óptimo","En proceso") -> En proceso | N20: =IF(A64>=CONFIG!$C$6/100,"✓ Día óptimo","En proceso") -> En proceso | Q20: =IF(A65>=CONFIG!$C$6/100,"✓ Día óptimo","En proceso") -> En proceso | T20: =IF(A66>=CONFIG!$C$6/100,"✓ Día óptimo","En proceso") -> En proceso
A60: =IFERROR(OFFSET(TRACKER!$B$36,0,(($U$3-1)*7+1)),0) -> 0.1 | B60: =1-A60 -> 0.9
A61: =IFERROR(OFFSET(TRACKER!$B$36,0,(($U$3-1)*7+2)),0) -> 0 | B61: =1-A61 -> 1
A62: =IFERROR(OFFSET(TRACKER!$B$36,0,(($U$3-1)*7+3)),0) -> 0.1 | B62: =1-A62 -> 0.9
A63: =IFERROR(OFFSET(TRACKER!$B$36,0,(($U$3-1)*7+4)),0) -> 0 | B63: =1-A63 -> 1
A64: =IFERROR(OFFSET(TRACKER!$B$36,0,(($U$3-1)*7+5)),0) -> 0 | B64: =1-A64 -> 1
A65: =IFERROR(OFFSET(TRACKER!$B$36,0,(($U$3-1)*7+6)),0) -> 0 | B65: =1-A65 -> 1
A66: =IFERROR(OFFSET(TRACKER!$B$36,0,(($U$3-1)*7+7)),0) -> 0 | B66: =1-A66 -> 1

Sheet DASHBOARD
B2: MONTHLY OVERVIEW
B3: =TEXT(DATE(CONFIG!C4,CONFIG!C5,1),"mmmm yyyy")&" · tus hábitos, de un vistazo" -> September 2026 · tus hábitos, de un vistazo
B4: PROMEDIO | E4: PROGRESO | H4: DÍAS OK | K4: RACHA | N4: FEELING 😊 | Q4: MEJOR DÍA
B5: =IFERROR(AVERAGE(TRACKER!B10:B19),0) -> 0.2 | E5: =IFERROR(SUM(TRACKER!C10:AG19)/(DAY(EOMONTH(DATE(CONFIG!C4,CONFIG!C5,1),0))*10),0) -> 0.0066666667 | H5: =COUNTIF(TRACKER!C23:AG23,"SI") -> 2 | K5: =IFERROR(INDEX(TRACKER!C24:AG24,SUMPRODUCT(MAX((TRACKER!C24:AG24<>"")*COLUMN(TRACKER!C24:AG24)))-COLUMN(TRACKER!C24)+1),0) -> 1 | N5: =IFERROR(AVERAGEIF(TRACKER!C22:AG22,">0",TRACKER!C22:AG22),0) -> 6.3333333 | Q5: =IFERROR(INDEX(TRACKER!C9:AG9,MATCH(MAX(TRACKER!C36:AG36),TRACKER!C36:AG36,0)),"-") -> 1
B10: HÁBITOS · CUMPLIMIENTO | G10: EVOLUCIÓN
B11: HÁBITO | C11: % | D11: DÍAS | E11: ESTADO | G11: DÍA | H11: SCORE | I11: % | J11: TODO OK? | K11: FEELING 😊 | U11: OBJETIVO
B12: =CONFIG!B9 -> Estudiar | C12: =IFERROR(SUM(TRACKER!C10:AG10)/DAY(EOMONTH(DATE(CONFIG!$C$4,CONFIG!$C$5,1),0)),0) -> 0.066666667 | D12: =SUM(TRACKER!C10:AG10) -> 2 | E12: =IF(C12>=CONFIG!C6/100,"ÓPTIMO",IF(C12>=0.5,"EN PROCESO","BAJO")) -> BAJO | G12: =TRACKER!C9 -> 1 | H12: =IFERROR(SUM(TRACKER!C10:C19),0) -> 1 | I12: =IFERROR(SUM(TRACKER!C10:C19)/10,0) -> 0.1 | J12: =TRACKER!C23 -> SI | K12: =TRACKER!C22 -> 7 | U12: =CONFIG!$C$6/100 -> 0.8
B13: =CONFIG!B10 -> Entrenar | C13: =IFERROR(SUM(TRACKER!C11:AG11)/DAY(EOMONTH(DATE(CONFIG!$C$4,CONFIG!$C$5,1),0)),0) -> 0 | D13: =SUM(TRACKER!C11:AG11) -> 0 | E13: =IF(C13>=CONFIG!C6/100,"ÓPTIMO",IF(C13>=0.5,"EN PROCESO","BAJO")) -> BAJO | G13: =TRACKER!D9 -> 2 | H13: =IFERROR(SUM(TRACKER!D10:D19),0) -> 0 | I13: =IFERROR(SUM(TRACKER!D10:D19)/10,0) -> 0 | J13: =TRACKER!D23 -> NO | K13: =TRACKER!D22 -> 4 | U13: =CONFIG!$C$6/100 -> 0.8
B14: =CONFIG!B11 -> Modulo Inglés | C14: =IFERROR(SUM(TRACKER!C12:AG12)/DAY(EOMONTH(DATE(CONFIG!$C$4,CONFIG!$C$5,1),0)),0) -> 0 | D14: =SUM(TRACKER!C12:AG12) -> 0 | E14: =IF(C14>=CONFIG!C6/100,"ÓPTIMO",IF(C14>=0.5,"EN PROCESO","BAJO")) -> BAJO | G14: =TRACKER!E9 -> 3 | H14: =IFERROR(SUM(TRACKER!E10:E19),0) -> 1 | I14: =IFERROR(SUM(TRACKER!E10:E19)/10,0) -> 0.1 | J14: =TRACKER!E23 -> SI | K14: =TRACKER!E22 -> 8 | U14: =CONFIG!$C$6/100 -> 0.8
B15: =CONFIG!B12 -> -Flashcards | C15: =IFERROR(SUM(TRACKER!C13:AG13)/DAY(EOMONTH(DATE(CONFIG!$C$4,CONFIG!$C$5,1),0)),0) -> 0 | D15: =SUM(TRACKER!C13:AG13) -> 0 | E15: =IF(C15>=CONFIG!C6/100,"ÓPTIMO",IF(C15>=0.5,"EN PROCESO","BAJO")) -> BAJO | G15: =TRACKER!F9 -> 4 | H15: =IFERROR(SUM(TRACKER!F10:F19),0) -> 0 | I15: =IFERROR(SUM(TRACKER!F10:F19)/10,0) -> 0 | J15: =TRACKER!F23 -> 0 | K15: =TRACKER!F22 -> 0 | U15: =CONFIG!$C$6/100 -> 0.8
B16: =CONFIG!B13 -> -Input / idioma | C16: =IFERROR(SUM(TRACKER!C14:AG14)/DAY(EOMONTH(DATE(CONFIG!$C$4,CONFIG!$C$5,1),0)),0) -> 0 | D16: =SUM(TRACKER!C14:AG14) -> 0 | E16: =IF(C16>=CONFIG!C6/100,"ÓPTIMO",IF(C16>=0.5,"EN PROCESO","BAJO")) -> BAJO | G16: =TRACKER!G9 -> 5 | H16: =IFERROR(SUM(TRACKER!G10:G19),0) -> 0 | I16: =IFERROR(SUM(TRACKER!G10:G19)/10,0) -> 0 | J16: =TRACKER!G23 -> 0 | K16: =TRACKER!G22 -> 0 | U16: =CONFIG!$C$6/100 -> 0.8
B17: =CONFIG!B14 -> -Lectura english | C17: =IFERROR(SUM(TRACKER!C15:AG15)/DAY(EOMONTH(DATE(CONFIG!$C$4,CONFIG!$C$5,1),0)),0) -> 0 | D17: =SUM(TRACKER!C15:AG15) -> 0 | E17: =IF(C17>=CONFIG!C6/100,"ÓPTIMO",IF(C17>=0.5,"EN PROCESO","BAJO")) -> BAJO | G17: =TRACKER!H9 -> 6 | H17: =IFERROR(SUM(TRACKER!H10:H19),0) -> 0 | I17: =IFERROR(SUM(TRACKER!H10:H19)/10,0) -> 0 | J17: =TRACKER!H23 -> 0 | K17: =TRACKER!H22 -> 0 | U17: =CONFIG!$C$6/100 -> 0.8
B18: =CONFIG!B15 -> -Grammar | C18: =IFERROR(SUM(TRACKER!C16:AG16)/DAY(EOMONTH(DATE(CONFIG!$C$4,CONFIG!$C$5,1),0)),0) -> 0 | D18: =SUM(TRACKER!C16:AG16) -> 0 | E18: =IF(C18>=CONFIG!C6/100,"ÓPTIMO",IF(C18>=0.5,"EN PROCESO","BAJO")) -> BAJO | G18: =TRACKER!I9 -> 7 | H18: =IFERROR(SUM(TRACKER!I10:I19),0) -> 0 | I18: =IFERROR(SUM(TRACKER!I10:I19)/10,0) -> 0 | J18: =TRACKER!I23 -> 0 | K18: =TRACKER!I22 -> 0 | U18: =CONFIG!$C$6/100 -> 0.8
B19: =CONFIG!B16 -> -Input Gamer | C19: =IFERROR(SUM(TRACKER!C17:AG17)/DAY(EOMONTH(DATE(CONFIG!$C$4,CONFIG!$C$5,1),0)),0) -> 0 | D19: =SUM(TRACKER!C17:AG17) -> 0 | E19: =IF(C19>=CONFIG!C6/100,"ÓPTIMO",IF(C19>=0.5,"EN PROCESO","BAJO")) -> BAJO | G19: =TRACKER!J9 -> 8 | H19: =IFERROR(SUM(TRACKER!J10:J19),0) -> 0 | I19: =IFERROR(SUM(TRACKER!J10:J19)/10,0) -> 0 | J19: =TRACKER!J23 -> 0 | K19: =TRACKER!J22 -> 0 | U19: =CONFIG!$C$6/100 -> 0.8
B20: =CONFIG!B17 -> Leer 1h | C20: =IFERROR(SUM(TRACKER!C18:AG18)/DAY(EOMONTH(DATE(CONFIG!$C$4,CONFIG!$C$5,1),0)),0) -> 0 | D20: =SUM(TRACKER!C18:AG18) -> 0 | E20: =IF(C20>=CONFIG!C6/100,"ÓPTIMO",IF(C20>=0.5,"EN PROCESO","BAJO")) -> BAJO | G20: =TRACKER!K9 -> 9 | H20: =IFERROR(SUM(TRACKER!K10:K19),0) -> 0 | I20: =IFERROR(SUM(TRACKER!K10:K19)/10,0) -> 0 | J20: =TRACKER!K23 -> 0 | K20: =TRACKER!K22 -> 0 | U20: =CONFIG!$C$6/100 -> 0.8
B21: =CONFIG!B18 -> Mindfulness | C21: =IFERROR(SUM(TRACKER!C19:AG19)/DAY(EOMONTH(DATE(CONFIG!$C$4,CONFIG!$C$5,1),0)),0) -> 0 | D21: =SUM(TRACKER!C19:AG19) -> 0 | E21: =IF(C21>=CONFIG!C6/100,"ÓPTIMO",IF(C21>=0.5,"EN PROCESO","BAJO")) -> BAJO | G21: =TRACKER!L9 -> 10 | H21: =IFERROR(SUM(TRACKER!L10:L19),0) -> 0 | I21: =IFERROR(SUM(TRACKER!L10:L19)/10,0) -> 0 | J21: =TRACKER!L23 -> 0 | K21: =TRACKER!L22 -> 0 | U21: =CONFIG!$C$6/100 -> 0.8
G22: =TRACKER!M9 -> 11 | H22: =IFERROR(SUM(TRACKER!M10:M19),0) -> 0 | I22: =IFERROR(SUM(TRACKER!M10:M19)/10,0) -> 0 | J22: =TRACKER!M23 -> 0 | K22: =TRACKER!M22 -> 0 | U22: =CONFIG!$C$6/100 -> 0.8
G23: =TRACKER!N9 -> 12 | H23: =IFERROR(SUM(TRACKER!N10:N19),0) -> 0 | I23: =IFERROR(SUM(TRACKER!N10:N19)/10,0) -> 0 | J23: =TRACKER!N23 -> 0 | K23: =TRACKER!N22 -> 0 | U23: =CONFIG!$C$6/100 -> 0.8
G24: =TRACKER!O9 -> 13 | H24: =IFERROR(SUM(TRACKER!O10:O19),0) -> 0 | I24: =IFERROR(SUM(TRACKER!O10:O19)/10,0) -> 0 | J24: =TRACKER!O23 -> 0 | K24: =TRACKER!O22 -> 0 | U24: =CONFIG!$C$6/100 -> 0.8
G25: =TRACKER!P9 -> 14 | H25: =IFERROR(SUM(TRACKER!P10:P19),0) -> 0 | I25: =IFERROR(SUM(TRACKER!P10:P19)/10,0) -> 0 | J25: =TRACKER!P23 -> 0 | K25: =TRACKER!P22 -> 0 | U25: =CONFIG!$C$6/100 -> 0.8
G26: =TRACKER!Q9 -> 15 | H26: =IFERROR(SUM(TRACKER!Q10:Q19),0) -> 0 | I26: =IFERROR(SUM(TRACKER!Q10:Q19)/10,0) -> 0 | J26: =TRACKER!Q23 -> 0 | K26: =TRACKER!Q22 -> 0 | U26: =CONFIG!$C$6/100 -> 0.8
G27: =TRACKER!R9 -> 16 | H27: =IFERROR(SUM(TRACKER!R10:R19),0) -> 0 | I27: =IFERROR(SUM(TRACKER!R10:R19)/10,0) -> 0 | J27: =TRACKER!R23 -> 0 | K27: =TRACKER!R22 -> 0 | U27: =CONFIG!$C$6/100 -> 0.8
G28: =TRACKER!S9 -> 17 | H28: =IFERROR(SUM(TRACKER!S10:S19),0) -> 0 | I28: =IFERROR(SUM(TRACKER!S10:S19)/10,0) -> 0 | J28: =TRACKER!S23 -> 0 | K28: =TRACKER!S22 -> 0 | U28: =CONFIG!$C$6/100 -> 0.8
G29: =TRACKER!T9 -> 18 | H29: =IFERROR(SUM(TRACKER!T10:T19),0) -> 0 | I29: =IFERROR(SUM(TRACKER!T10:T19)/10,0) -> 0 | J29: =TRACKER!T23 -> 0 | K29: =TRACKER!T22 -> 0 | U29: =CONFIG!$C$6/100 -> 0.8
G30: =TRACKER!U9 -> 19 | H30: =IFERROR(SUM(TRACKER!U10:U19),0) -> 0 | I30: =IFERROR(SUM(TRACKER!U10:U19)/10,0) -> 0 | J30: =TRACKER!U23 -> 0 | K30: =TRACKER!U22 -> 0 | U30: =CONFIG!$C$6/100 -> 0.8
G31: =TRACKER!V9 -> 20 | H31: =IFERROR(SUM(TRACKER!V10:V19),0) -> 0 | I31: =IFERROR(SUM(TRACKER!V10:V19)/10,0) -> 0 | J31: =TRACKER!V23 -> 0 | K31: =TRACKER!V22 -> 0 | U31: =CONFIG!$C$6/100 -> 0.8
G32: =TRACKER!W9 -> 21 | H32: =IFERROR(SUM(TRACKER!W10:W19),0) -> 0 | I32: =IFERROR(SUM(TRACKER!W10:W19)/10,0) -> 0 | J32: =TRACKER!W23 -> 0 | K32: =TRACKER!W22 -> 0 | U32: =CONFIG!$C$6/100 -> 0.8
G33: =TRACKER!X9 -> 22 | H33: =IFERROR(SUM(TRACKER!X10:X19),0) -> 0 | I33: =IFERROR(SUM(TRACKER!X10:X19)/10,0) -> 0 | J33: =TRACKER!X23 -> 0 | K33: =TRACKER!X22 -> 0 | U33: =CONFIG!$C$6/100 -> 0.8
G34: =TRACKER!Y9 -> 23 | H34: =IFERROR(SUM(TRACKER!Y10:Y19),0) -> 0 | I34: =IFERROR(SUM(TRACKER!Y10:Y19)/10,0) -> 0 | J34: =TRACKER!Y23 -> 0 | K34: =TRACKER!Y22 -> 0 | U34: =CONFIG!$C$6/100 -> 0.8
G35: =TRACKER!Z9 -> 24 | H35: =IFERROR(SUM(TRACKER!Z10:Z19),0) -> 0 | I35: =IFERROR(SUM(TRACKER!Z10:Z19)/10,0) -> 0 | J35: =TRACKER!Z23 -> 0 | K35: =TRACKER!Z22 -> 0 | U35: =CONFIG!$C$6/100 -> 0.8
G36: =TRACKER!AA9 -> 25 | H36: =IFERROR(SUM(TRACKER!AA10:AA19),0) -> 0 | I36: =IFERROR(SUM(TRACKER!AA10:AA19)/10,0) -> 0 | J36: =TRACKER!AA23 -> 0 | K36: =TRACKER!AA22 -> 0 | U36: =CONFIG!$C$6/100 -> 0.8
G37: =TRACKER!AB9 -> 26 | H37: =IFERROR(SUM(TRACKER!AB10:AB19),0) -> 0 | I37: =IFERROR(SUM(TRACKER!AB10:AB19)/10,0) -> 0 | J37: =TRACKER!AB23 -> 0 | K37: =TRACKER!AB22 -> 0 | U37: =CONFIG!$C$6/100 -> 0.8
G38: =TRACKER!AC9 -> 27 | H38: =IFERROR(SUM(TRACKER!AC10:AC19),0) -> 0 | I38: =IFERROR(SUM(TRACKER!AC10:AC19)/10,0) -> 0 | J38: =TRACKER!AC23 -> 0 | K38: =TRACKER!AC22 -> 0 | U38: =CONFIG!$C$6/100 -> 0.8
G39: =TRACKER!AD9 -> 28 | H39: =IFERROR(SUM(TRACKER!AD10:AD19),0) -> 0 | I39: =IFERROR(SUM(TRACKER!AD10:AD19)/10,0) -> 0 | J39: =TRACKER!AD23 -> 0 | K39: =TRACKER!AD22 -> 0 | U39: =CONFIG!$C$6/100 -> 0.8
G40: =TRACKER!AE9 -> 29 | H40: =IFERROR(SUM(TRACKER!AE10:AE19),0) -> 0 | I40: =IFERROR(SUM(TRACKER!AE10:AE19)/10,0) -> 0 | J40: =TRACKER!AE23 -> 0 | K40: =TRACKER!AE22 -> 0 | U40: =CONFIG!$C$6/100 -> 0.8
G41: =TRACKER!AF9 -> 30 | H41: =IFERROR(SUM(TRACKER!AF10:AF19),0) -> 0 | I41: =IFERROR(SUM(TRACKER!AF10:AF19)/10,0) -> 0 | J41: =TRACKER!AF23 -> 0 | K41: =TRACKER!AF22 -> 0 | U41: =CONFIG!$C$6/100 -> 0.8
G42: =TRACKER!AG9 | H42: =IFERROR(SUM(TRACKER!AG10:AG19),0) -> 0 | I42: =IFERROR(SUM(TRACKER!AG10:AG19)/10,0) -> 0 | J42: =TRACKER!AG23 -> 0 | K42: =TRACKER!AG22 -> 0 | U42: =CONFIG!$C$6/100 -> 0.8
B43: 0 / 1 = hábitos · TODO OK? = evaluación general · FEELING = 1–10
B45: HÁBITOS · GRÁFICOS
V61: ESTADO | W61: DIAS
...

Sheet CONFIG
B2: CONFIGURACIÓN
B4: Año | C4: 2026 | E4: Meta de sueño (hs) | F4: 8
B5: Mes (1–12) | C5: 9 | E5: Meta de calorías (kcal) | F5: 2000
B6: Objetivo diario (%) | C6: 80 | D6: Día considerado cumplido si alcanza este porcentaje.
B8: TUS 10 HÁBITOS
B9: Estudiar
B10: Entrenar
B11: Modulo Inglés
B12: -Flashcards
B13: -Input / idioma
B14: -Lectura english
B15: -Grammar
B16: -Input Gamer
B17: Leer 1h
B18: Mindfulness

Sheet FOCUS
B2: MODO FOCUS
B3: Un corte, una tarea. Sin distracciones.
B5: TAREA ACTUAL
B6: Estudiar
B9: TEMPORIZADOR
B10: Inicio | C10: 09:00
B11: Duración (min) | C11: 50
B12: Fin | C12: =IF(C10="","",TEXT(TIMEVALUE(C10)+ (C11/1440),"hh:mm")) -> 09:50
B15: "La disciplina no ruge todos los días. Solo corta, en silencio, una vez más."
